[01mRunning Sphinx v8.2.3[39;49;00m
[01mloading translations [en]... [39;49;00mdone
[01mloading pickled environment... [39;49;00mThe configuration has changed (3 options: 'html_css_files', 'html_static_path', 'pygments_dark_style')
done
loading intersphinx inventory 'python' from https://docs.python.org/3/objects.inv ...
loading intersphinx inventory 'django' from https://docs.djangoproject.com/en/stable/_objects/ ...
loading intersphinx inventory 'psa' from https://python-social-auth.readthedocs.io/en/latest/objects.inv ...
loading intersphinx inventory 'tt' from https://docs.translatehouse.org/projects/translate-toolkit/en/latest/objects.inv ...
loading intersphinx inventory 'amagama' from https://docs.translatehouse.org/projects/amagama/en/latest/objects.inv ...
loading intersphinx inventory 'virtaal' from https://docs.translatehouse.org/projects/virtaal/en/latest/objects.inv ...
loading intersphinx inventory 'ldap' from https://django-auth-ldap.readthedocs.io/en/latest/objects.inv ...
[91mWARNING: failed to reach any of the inventories with the following issues:
intersphinx inventory 'https://python-social-auth.readthedocs.io/en/latest/objects.inv' not fetchable due to <class 'requests.exceptions.ConnectionError'>: HTTPSConnectionPool(host='python-social-auth.readthedocs.io', port=443): Max retries exceeded with url: /en/latest/objects.inv (Caused by NameResolutionError("<urllib3.connection.HTTPSConnection object at 0x7f96c61ce300>: Failed to resolve 'python-social-auth.readthedocs.io' ([Errno -5] No address associated with hostname)"))[39;49;00m
loading intersphinx inventory 'celery' from https://docs.celeryq.dev/en/stable/objects.inv ...
[91mWARNING: failed to reach any of the inventories with the following issues:
intersphinx inventory 'https://docs.translatehouse.org/projects/amagama/en/latest/objects.inv' not fetchable due to <class 'requests.exceptions.ConnectionError'>: HTTPSConnectionPool(host='docs.translatehouse.org', port=443): Max retries exceeded with url: /projects/amagama/en/latest/objects.inv (Caused by NameResolutionError("<urllib3.connection.HTTPSConnection object at 0x7f96c61cf650>: Failed to resolve 'docs.translatehouse.org' ([Errno -5] No address associated with hostname)"))[39;49;00m
[91mWARNING: failed to reach any of the inventories with the following issues:
intersphinx inventory 'https://docs.translatehouse.org/projects/translate-toolkit/en/latest/objects.inv' not fetchable due to <class 'requests.exceptions.ConnectionError'>: HTTPSConnectionPool(host='docs.translatehouse.org', port=443): Max retries exceeded with url: /projects/translate-toolkit/en/latest/objects.inv (Caused by NameResolutionError("<urllib3.connection.HTTPSConnection object at 0x7f96c61cec60>: Failed to resolve 'docs.translatehouse.org' ([Errno -5] No address associated with hostname)"))[39;49;00m
[91mWARNING: failed to reach any of the inventories with the following issues:
intersphinx inventory 'https://docs.djangoproject.com/en/stable/_objects/' not fetchable due to <class 'requests.exceptions.ConnectionError'>: HTTPSConnectionPool(host='docs.djangoproject.com', port=443): Max retries exceeded with url: /en/stable/_objects/ (Caused by NameResolutionError("<urllib3.connection.HTTPSConnection object at 0x7f96c6a65b50>: Failed to resolve 'docs.djangoproject.com' ([Errno -5] No address associated with hostname)"))[39;49;00m
[91mWARNING: failed to reach any of the inventories with the following issues:
intersphinx inventory 'https://docs.translatehouse.org/projects/virtaal/en/latest/objects.inv' not fetchable due to <class 'requests.exceptions.ConnectionError'>: HTTPSConnectionPool(host='docs.translatehouse.org', port=443): Max retries exceeded with url: /projects/virtaal/en/latest/objects.inv (Caused by NameResolutionError("<urllib3.connection.HTTPSConnection object at 0x7f96c6240050>: Failed to resolve 'docs.translatehouse.org' ([Errno -5] No address associated with hostname)"))[39;49;00m
[91mWARNING: failed to reach any of the inventories with the following issues:
intersphinx inventory 'https://docs.python.org/3/objects.inv' not fetchable due to <class 'requests.exceptions.ConnectionError'>: HTTPSConnectionPool(host='docs.python.org', port=443): Max retries exceeded with url: /3/objects.inv (Caused by NameResolutionError("<urllib3.connection.HTTPSConnection object at 0x7f96c61ce450>: Failed to resolve 'docs.python.org' ([Errno -5] No address associated with hostname)"))[39;49;00m
loading intersphinx inventory 'sphinx' from https://www.sphinx-doc.org/en/master/objects.inv ...
loading intersphinx inventory 'rtd' from https://docs.readthedocs.io/en/latest/objects.inv ...
[91mWARNING: failed to reach any of the inventories with the following issues:
intersphinx inventory 'https://docs.celeryq.dev/en/stable/objects.inv' not fetchable due to <class 'requests.exceptions.ConnectionError'>: HTTPSConnectionPool(host='docs.celeryq.dev', port=443): Max retries exceeded with url: /en/stable/objects.inv (Caused by NameResolutionError("<urllib3.connection.HTTPSConnection object at 0x7f96c6241010>: Failed to resolve 'docs.celeryq.dev' ([Errno -5] No address associated with hostname)"))[39;49;00m
loading intersphinx inventory 'venv' from https://virtualenv.pypa.io/en/stable/objects.inv ...
loading intersphinx inventory 'borg' from https://borgbackup.readthedocs.io/en/stable/objects.inv ...
[91mWARNING: failed to reach any of the inventories with the following issues:
intersphinx inventory 'https://django-auth-ldap.readthedocs.io/en/latest/objects.inv' not fetchable due to <class 'requests.exceptions.ConnectionError'>: HTTPSConnectionPool(host='django-auth-ldap.readthedocs.io', port=443): Max retries exceeded with url: /en/latest/objects.inv (Caused by NameResolutionError("<urllib3.connection.HTTPSConnection object at 0x7f96c6241130>: Failed to resolve 'django-auth-ldap.readthedocs.io' ([Errno -5] No address associated with hostname)"))[39;49;00m
loading intersphinx inventory 'compressor' from https://django-compressor.readthedocs.io/en/stable/objects.inv ...
loading intersphinx inventory 'drf-standardized-error' from https://drf-standardized-errors.readthedocs.io/en/latest/objects.inv ...
[91mWARNING: failed to reach any of the inventories with the following issues:
intersphinx inventory 'https://drf-standardized-errors.readthedocs.io/en/latest/objects.inv' not fetchable due to <class 'requests.exceptions.ConnectionError'>: HTTPSConnectionPool(host='drf-standardized-errors.readthedocs.io', port=443): Max retries exceeded with url: /en/latest/objects.inv (Caused by NameResolutionError("<urllib3.connection.HTTPSConnection object at 0x7f96c61cf140>: Failed to resolve 'drf-standardized-errors.readthedocs.io' ([Errno -5] No address associated with hostname)"))[39;49;00m
[91mWARNING: failed to reach any of the inventories with the following issues:
intersphinx inventory 'https://virtualenv.pypa.io/en/stable/objects.inv' not fetchable due to <class 'requests.exceptions.ConnectionError'>: HTTPSConnectionPool(host='virtualenv.pypa.io', port=443): Max retries exceeded with url: /en/stable/objects.inv (Caused by NameResolutionError("<urllib3.connection.HTTPSConnection object at 0x7f96c6a4b3b0>: Failed to resolve 'virtualenv.pypa.io' ([Errno -5] No address associated with hostname)"))[39;49;00m
[91mWARNING: failed to reach any of the inventories with the following issues:
intersphinx inventory 'https://docs.readthedocs.io/en/latest/objects.inv' not fetchable due to <class 'requests.exceptions.ConnectionError'>: HTTPSConnectionPool(host='docs.readthedocs.io', port=443): Max retries exceeded with url: /en/latest/objects.inv (Caused by NameResolutionError("<urllib3.connection.HTTPSConnection object at 0x7f96c62424b0>: Failed to resolve 'docs.readthedocs.io' ([Errno -5] No address associated with hostname)"))[39;49;00m
[91mWARNING: failed to reach any of the inventories with the following issues:
intersphinx inventory 'https://django-compressor.readthedocs.io/en/stable/objects.inv' not fetchable due to <class 'requests.exceptions.ConnectionError'>: HTTPSConnectionPool(host='django-compressor.readthedocs.io', port=443): Max retries exceeded with url: /en/stable/objects.inv (Caused by NameResolutionError("<urllib3.connection.HTTPSConnection object at 0x7f96c61cd5e0>: Failed to resolve 'django-compressor.readthedocs.io' ([Errno -5] No address associated with hostname)"))[39;49;00m
[91mWARNING: failed to reach any of the inventories with the following issues:
intersphinx inventory 'https://www.sphinx-doc.org/en/master/objects.inv' not fetchable due to <class 'requests.exceptions.ConnectionError'>: HTTPSConnectionPool(host='www.sphinx-doc.org', port=443): Max retries exceeded with url: /en/master/objects.inv (Caused by NameResolutionError("<urllib3.connection.HTTPSConnection object at 0x7f96c6241c10>: Failed to resolve 'www.sphinx-doc.org' ([Errno -5] No address associated with hostname)"))[39;49;00m
[91mWARNING: failed to reach any of the inventories with the following issues:
intersphinx inventory 'https://borgbackup.readthedocs.io/en/stable/objects.inv' not fetchable due to <class 'requests.exceptions.ConnectionError'>: HTTPSConnectionPool(host='borgbackup.readthedocs.io', port=443): Max retries exceeded with url: /en/stable/objects.inv (Caused by NameResolutionError("<urllib3.connection.HTTPSConnection object at 0x7f96c61cfd40>: Failed to resolve 'borgbackup.readthedocs.io' ([Errno -5] No address associated with hostname)"))[39;49;00m
[01mbuilding [mo]: [39;49;00mtargets for 0 po files that are out of date
[01mwriting output... [39;49;00m
[01mbuilding [html]: [39;49;00mtargets for 0 source files that are out of date
[01mupdating environment: [39;49;00m0 added, 0 changed, 0 removed
[01mreading sources... [39;49;00m
[01mlooking for now-outdated files... [39;49;00mnone found
[01mno targets are out of date.[39;49;00m
[01mpreparing documents... [39;49;00mdone
[01mcopying assets... [39;49;00m
[01mcopying static files... [39;49;00m
Writing evaluated template result to /home/runner/work/weblate/weblate/docs/_build/html/_static/language_data.js
Writing evaluated template result to /home/runner/work/weblate/weblate/docs/_build/html/_static/basic.css
Writing evaluated template result to /home/runner/work/weblate/weblate/docs/_build/html/_static/documentation_options.js
Writing evaluated template result to /home/runner/work/weblate/weblate/docs/_build/html/_static/copybutton.js
[01mcopying static files: [39;49;00mdone
[01mcopying extra files... [39;49;00m
[01mcopying extra files: [39;49;00mdone
[01mcopying assets: [39;49;00mdone
[01mgenerating indices... [39;49;00mgenindex http-routingtable py-modindex done
Overwriting 'devel/thirdparty.html' with redirect to 'third-party.html'.
Overwriting 'contributing/security.html' with redirect to 'security/index.html'.
Overwriting 'formats/moko.html' with redirect to 'formats/moko-resources.html'.
[01mwriting additional pages... [39;49;00msearch done
[01mdumping search index in English (code: en)... [39;49;00mdone
[01mdumping object inventory... [39;49;00mdone
[01mbuild succeeded, 14 warnings.[39;49;00m

The HTML pages are in _build/html.
